<?xml version="1.0" ?>
<!-- =================================================================================== -->
<!-- |    This document was autogenerated by xacro from cob3-1.urdf.xacro              | -->
<!-- |    EDITING THIS FILE BY HAND IS NOT RECOMMENDED                                 | -->
<!-- =================================================================================== -->
<robot name="cob3-1" xmlns:xacro="http://www.ros.org/wiki/xacro">
  <!-- common stuff -->
  <material name="IPA/LightGrey">
    <color rgba="0.7 0.7 0.7 1.0"/>
  </material>
  <material name="IPA/DarkGrey">
    <color rgba="0.4 0.4 0.4 1.0"/>
  </material>
  <material name="IPA/Orange">
    <color rgba="1.0 0.4 0.0 1.0"/>
  </material>
  <material name="IPA/Black">
    <color rgba="0.0 0.0 0.0 1.0"/>
  </material>
  <material name="IPA/Blue">
    <color rgba="0.0 0.0 0.5 1.0"/>
  </material>
  <material name="Schunk/LightGrey">
    <color rgba="0.7 0.7 0.7 1.0"/>
  </material>
  <material name="Schunk/DarkGrey">
    <color rgba="0.4 0.4 0.4 1.0"/>
  </material>
  <material name="Schunk/Black">
    <color rgba="0.0 0.0 0.0 1.0"/>
  </material>
  <material name="Schunk/DarkGolden">
    <color rgba="0.4 0.4 0.3 1.0"/>
  </material>
  <material name="Schunk/Blue">
    <color rgba="0.0 0.0 0.8 1.0"/>
  </material>
  <!-- calibration -->
  <!-- base -->
  <!-- tray -->
  <!-- torso -->
  <!-- head -->
  <!-- arm -->
  <!-- sdh -->
  <!-- generic simulator_gazebo plugins for starting mechanism control, ros time, ros battery -->
  <gazebo>
    <plugin filename="libgazebo_ros_control.so" name="ros_control">
      <!--robotNamespace>/</robotNamespace-->
      <!--robotSimType>gazebo_ros_control/DefaultRobotHWSim</robotSimType-->
    </plugin>
  </gazebo>
  <!-- composition of the robot -->
  <link name="base_link">
    <inertial>
      <mass value="116.0"/>
      <origin xyz="0 0 0"/>
      <inertia ixx="5.652232699207" ixy="-0.009719934438" ixz="1.293988226423" iyy="5.669473158652" iyz="-0.007379583694" izz="3.683196351726"/>
    </inertial>
    <visual>
      <origin rpy="0 0 0" xyz="0 0 0"/>
      <geometry>
        <mesh filename="package://cob_description/meshes/cob3_base/base.stl"/>
        <!--box size="${base_size_x} ${base_size_y} ${base_collision_size_z}" /-->
      </geometry>
      <material name="IPA/LightGrey"/>
    </visual>
    <collision>
      <origin rpy="0 0 0" xyz="0 0 0"/>
      <geometry>
        <mesh filename="package://cob_description/meshes/cob3_base/base_collision.stl"/>
        <!--box size="${base_size_x} ${base_size_y} ${base_collision_size_z}" /-->
      </geometry>
    </collision>
  </link>
  <link name="base_footprint"/>
  <joint name="base_footprint_joint" type="fixed">
    <origin rpy="0 0 0" xyz="0 0 0"/>
    <child link="base_link"/>
    <parent link="base_footprint"/>
  </joint>
  <joint name="base_laser_front_joint" type="fixed">
    <axis xyz="0 1 0"/>
    <origin rpy="0.0 0.0 0.0" xyz="0.325 0.0 0.135"/>
    <parent link="base_link"/>
    <child link="base_laser_front_link"/>
  </joint>
  <link name="base_laser_front_link" type="laser">
    <inertial>
      <mass value="0.001"/>
      <origin rpy="0 0 0" xyz="0 0 0"/>
      <inertia ixx="0.0001" ixy="0" ixz="0" iyy="0.000001" iyz="0" izz="0.0001"/>
    </inertial>
    <visual>
      <origin rpy="0 0 0" xyz="0 0 0"/>
      <geometry>
        <mesh filename="package://cob_description/meshes/sensors/sick_s300_laser.dae"/>
        <!--box size="0.001 0.001 0.001" /-->
      </geometry>
      <material name="IPA/LightGrey"/>
    </visual>
    <collision>
      <origin rpy="0 0 0" xyz="0 0 0"/>
      <geometry>
        <cylinder length="0.09" radius="0.044"/>
      </geometry>
    </collision>
  </link>
  <gazebo reference="base_laser_front_link">
    <sensor name="base_laser_front" type="ray">
      <always_on>true</always_on>
      <update_rate>10</update_rate>
      <pose>0 0 0 0 0 0</pose>
      <visualize>false</visualize>
      <ray>
        <scan>
          <horizontal>
            <samples>541</samples>
            <resolution>1.0</resolution>
            <min_angle>-2.3562</min_angle>
            <max_angle>2.3562</max_angle>
          </horizontal>
        </scan>
        <range>
          <min>0.05</min>
          <max>30.0</max>
          <resolution>0.03</resolution>
        </range>
      </ray>
      <plugin filename="libgazebo_ros_laser.so" name="gazebo_ros_base_laser_front_controller">
        <gaussianNoise>0.005</gaussianNoise>
        <alwaysOn>true</alwaysOn>
        <updateRate>10</updateRate>
        <topicName>scan_front_raw</topicName>
        <frameName>base_laser_front_link</frameName>
        <hokuyoMinIntensity>101.0</hokuyoMinIntensity>
      </plugin>
    </sensor>
    <!--material value="IPA/LightGrey" /-->
  </gazebo>
  <joint name="base_laser_rear_joint" type="fixed">
    <axis xyz="0 1 0"/>
    <origin rpy="0.0 0.0 3.1415926" xyz="-0.325 0.0 0.135"/>
    <parent link="base_link"/>
    <child link="base_laser_rear_link"/>
  </joint>
  <link name="base_laser_rear_link" type="laser">
    <inertial>
      <mass value="0.001"/>
      <origin rpy="0 0 0" xyz="0 0 0"/>
      <inertia ixx="0.0001" ixy="0" ixz="0" iyy="0.000001" iyz="0" izz="0.0001"/>
    </inertial>
    <visual>
      <origin rpy="0 0 0" xyz="0 0 0"/>
      <geometry>
        <mesh filename="package://cob_description/meshes/sensors/sick_s300_laser.dae"/>
        <!--box size="0.001 0.001 0.001" /-->
      </geometry>
      <material name="IPA/LightGrey"/>
    </visual>
    <collision>
      <origin rpy="0 0 0" xyz="0 0 0"/>
      <geometry>
        <cylinder length="0.09" radius="0.044"/>
      </geometry>
    </collision>
  </link>
  <gazebo reference="base_laser_rear_link">
    <sensor name="base_laser_rear" type="ray">
      <always_on>true</always_on>
      <update_rate>10</update_rate>
      <pose>0 0 0 0 0 0</pose>
      <visualize>false</visualize>
      <ray>
        <scan>
          <horizontal>
            <samples>541</samples>
            <resolution>1.0</resolution>
            <min_angle>-2.3562</min_angle>
            <max_angle>2.3562</max_angle>
          </horizontal>
        </scan>
        <range>
          <min>0.05</min>
          <max>30.0</max>
          <resolution>0.03</resolution>
        </range>
      </ray>
      <plugin filename="libgazebo_ros_laser.so" name="gazebo_ros_base_laser_rear_controller">
        <gaussianNoise>0.005</gaussianNoise>
        <alwaysOn>true</alwaysOn>
        <updateRate>10</updateRate>
        <topicName>scan_rear_raw</topicName>
        <frameName>base_laser_rear_link</frameName>
        <hokuyoMinIntensity>101.0</hokuyoMinIntensity>
      </plugin>
    </sensor>
    <!--material value="IPA/LightGrey" /-->
  </gazebo>
  <joint name="base_laser_top_joint" type="fixed">
    <axis xyz="0 1 0"/>
    <origin rpy="0.0 0.0 0.0" xyz="-0.252 0.0 0.42"/>
    <parent link="base_link"/>
    <child link="base_laser_top_link"/>
  </joint>
  <link name="base_laser_top_link" type="laser"/>
  <gazebo reference="base_laser_top_link">
    <sensor name="base_laser_top" type="ray">
      <always_on>true</always_on>
      <update_rate>10</update_rate>
      <pose>0 0 0 0 0 0</pose>
      <visualize>false</visualize>
      <ray>
        <scan>
          <horizontal>
            <samples>640</samples>
            <resolution>1.0</resolution>
            <min_angle>-2.3562</min_angle>
            <max_angle>2.3562</max_angle>
          </horizontal>
        </scan>
        <range>
          <min>0.05</min>
          <max>10.0</max>
          <resolution>0.01</resolution>
        </range>
      </ray>
      <plugin filename="libgazebo_ros_laser.so" name="gazebo_ros_base_laser_top_controller">
        <gaussianNoise>0.005</gaussianNoise>
        <alwaysOn>true</alwaysOn>
        <updateRate>10</updateRate>
        <topicName>scan_top_raw</topicName>
        <frameName>base_laser_top_link</frameName>
        <hokuyoMinIntensity>101.0</hokuyoMinIntensity>
      </plugin>
    </sensor>
    <material>IPA/LightGrey</material>
  </gazebo>
  <joint name="fl_caster_rotation_joint" type="continuous">
    <axis xyz="0 0 1"/>
    <limit effort="100" velocity="100"/>
    <!-- alpha tested velocity and effort limits -->
    <safety_controller k_velocity="10"/>
    <calibration rising="-0.785398163397"/>
    <dynamics damping="0.0" friction="0.0"/>
    <origin rpy="0 0 0" xyz="0.235 0.185 0.075"/>
    <parent link="base_link"/>
    <child link="fl_caster_rotation_link"/>
  </joint>
  <link name="fl_caster_rotation_link">
    <inertial>
      <mass value="5.9"/>
      <origin xyz="0 0 0"/>
      <inertia ixx="0.04" ixy="-0.0007" ixz="0.0" iyy="0.02" iyz="-0.000004" izz="0.05"/>
    </inertial>
    <visual>
      <origin rpy="0 0 0" xyz="0 0 0"/>
      <geometry>
        <mesh filename="package://cob_description/meshes/cob3_base/caster.stl"/>
        <!--box size="0.001 0.001 0.001" /-->
      </geometry>
      <material name="IPA/LightGrey"/>
    </visual>
    <collision>
      <origin rpy="0 0 0" xyz="0 0 0"/>
      <geometry>
        <box size="0.001 0.001 0.001"/>
      </geometry>
    </collision>
  </link>
  <transmission name="fl_caster_rotation_trans">
    <type>transmission_interface/SimpleTransmission</type>
    <joint name="fl_caster_rotation_joint"/>
    <actuator name="fl_caster_rotation_motor">
      <hardwareInterface>EffortJointInterface</hardwareInterface>
      <mechanicalReduction>-79.2380952381</mechanicalReduction>
    </actuator>
  </transmission>
  <joint name="fl_caster_r_wheel_joint" type="continuous">
    <axis xyz="0 1 0"/>
    <limit effort="100" velocity="100"/>
    <!-- alpha tested effort and velocity limits -->
    <safety_controller k_velocity="10"/>
    <dynamics damping="0.0" friction="0.0"/>
    <origin rpy="0 0 0" xyz="0 -0.0 0"/>
    <parent link="fl_caster_rotation_link"/>
    <child link="fl_caster_r_wheel_link"/>
  </joint>
  <link name="fl_caster_r_wheel_link">
    <inertial>
      <mass value="0.44036"/>
      <origin xyz="0 0 0"/>
      <inertia ixx="0.012411765597" ixy="-0.000711733678" ixz="0.00050272983" iyy="0.015218160428" iyz="-0.000004273467" izz="0.011763977943"/>
    </inertial>
    <visual>
      <origin rpy="1.57079632679 0 0" xyz="0 0 0"/>
      <geometry>
        <cylinder length="0.034" radius="0.074792"/>
      </geometry>
      <material name="IPA/LightGrey"/>
    </visual>
    <collision>
      <origin rpy="1.57079632679 0 0" xyz="0 0 0"/>
      <!-- rotation because cyl. geom primitive has symmetry axis in +x direction -->
      <geometry>
        <cylinder length="0.034" radius="0.074792"/>
      </geometry>
    </collision>
  </link>
  <gazebo reference="fl_caster_r_wheel_link">
    <mu1 value="100.0"/>
    <mu2 value="100.0"/>
    <kp value="1000000.0"/>
    <kd value="1.0"/>
    <material value="IPA/LightGrey"/>
  </gazebo>
  <transmission name="fl_caster_r_wheel_trans">
    <type>transmission_interface/SimpleTransmission</type>
    <joint name="fl_caster_r_wheel_joint"/>
    <actuator name="fl_caster_r_wheel_motor">
      <hardwareInterface>EffortJointInterface</hardwareInterface>
      <mechanicalReduction>-79.2380952381</mechanicalReduction>
    </actuator>
  </transmission>
  <gazebo reference="fl_caster_rotation_link">
    <material value="IPA/Metal"/>
  </gazebo>
  <joint name="fr_caster_rotation_joint" type="continuous">
    <axis xyz="0 0 1"/>
    <limit effort="100" velocity="100"/>
    <!-- alpha tested velocity and effort limits -->
    <safety_controller k_velocity="10"/>
    <calibration rising="-0.785398163397"/>
    <dynamics damping="0.0" friction="0.0"/>
    <origin rpy="0 0 0" xyz="0.235 -0.185 0.075"/>
    <parent link="base_link"/>
    <child link="fr_caster_rotation_link"/>
  </joint>
  <link name="fr_caster_rotation_link">
    <inertial>
      <mass value="5.9"/>
      <origin xyz="0 0 0"/>
      <inertia ixx="0.04" ixy="-0.0007" ixz="0.0" iyy="0.02" iyz="-0.000004" izz="0.05"/>
    </inertial>
    <visual>
      <origin rpy="0 0 0" xyz="0 0 0"/>
      <geometry>
        <mesh filename="package://cob_description/meshes/cob3_base/caster.stl"/>
        <!--box size="0.001 0.001 0.001" /-->
      </geometry>
      <material name="IPA/LightGrey"/>
    </visual>
    <collision>
      <origin rpy="0 0 0" xyz="0 0 0"/>
      <geometry>
        <box size="0.001 0.001 0.001"/>
      </geometry>
    </collision>
  </link>
  <transmission name="fr_caster_rotation_trans">
    <type>transmission_interface/SimpleTransmission</type>
    <joint name="fr_caster_rotation_joint"/>
    <actuator name="fr_caster_rotation_motor">
      <hardwareInterface>EffortJointInterface</hardwareInterface>
      <mechanicalReduction>-79.2380952381</mechanicalReduction>
    </actuator>
  </transmission>
  <joint name="fr_caster_r_wheel_joint" type="continuous">
    <axis xyz="0 1 0"/>
    <limit effort="100" velocity="100"/>
    <!-- alpha tested effort and velocity limits -->
    <safety_controller k_velocity="10"/>
    <dynamics damping="0.0" friction="0.0"/>
    <origin rpy="0 0 0" xyz="0 -0.0 0"/>
    <parent link="fr_caster_rotation_link"/>
    <child link="fr_caster_r_wheel_link"/>
  </joint>
  <link name="fr_caster_r_wheel_link">
    <inertial>
      <mass value="0.44036"/>
      <origin xyz="0 0 0"/>
      <inertia ixx="0.012411765597" ixy="-0.000711733678" ixz="0.00050272983" iyy="0.015218160428" iyz="-0.000004273467" izz="0.011763977943"/>
    </inertial>
    <visual>
      <origin rpy="1.57079632679 0 0" xyz="0 0 0"/>
      <geometry>
        <cylinder length="0.034" radius="0.074792"/>
      </geometry>
      <material name="IPA/LightGrey"/>
    </visual>
    <collision>
      <origin rpy="1.57079632679 0 0" xyz="0 0 0"/>
      <!-- rotation because cyl. geom primitive has symmetry axis in +x direction -->
      <geometry>
        <cylinder length="0.034" radius="0.074792"/>
      </geometry>
    </collision>
  </link>
  <gazebo reference="fr_caster_r_wheel_link">
    <mu1 value="100.0"/>
    <mu2 value="100.0"/>
    <kp value="1000000.0"/>
    <kd value="1.0"/>
    <material value="IPA/LightGrey"/>
  </gazebo>
  <transmission name="fr_caster_r_wheel_trans">
    <type>transmission_interface/SimpleTransmission</type>
    <joint name="fr_caster_r_wheel_joint"/>
    <actuator name="fr_caster_r_wheel_motor">
      <hardwareInterface>EffortJointInterface</hardwareInterface>
      <mechanicalReduction>-79.2380952381</mechanicalReduction>
    </actuator>
  </transmission>
  <gazebo reference="fr_caster_rotation_link">
    <material value="IPA/Metal"/>
  </gazebo>
  <joint name="bl_caster_rotation_joint" type="continuous">
    <axis xyz="0 0 1"/>
    <limit effort="100" velocity="100"/>
    <!-- alpha tested velocity and effort limits -->
    <safety_controller k_velocity="10"/>
    <calibration rising="2.35619449019"/>
    <dynamics damping="0.0" friction="0.0"/>
    <origin rpy="0 0 0" xyz="-0.235 0.185 0.075"/>
    <parent link="base_link"/>
    <child link="bl_caster_rotation_link"/>
  </joint>
  <link name="bl_caster_rotation_link">
    <inertial>
      <mass value="5.9"/>
      <origin xyz="0 0 0"/>
      <inertia ixx="0.04" ixy="-0.0007" ixz="0.0" iyy="0.02" iyz="-0.000004" izz="0.05"/>
    </inertial>
    <visual>
      <origin rpy="0 0 0" xyz="0 0 0"/>
      <geometry>
        <mesh filename="package://cob_description/meshes/cob3_base/caster.stl"/>
        <!--box size="0.001 0.001 0.001" /-->
      </geometry>
      <material name="IPA/LightGrey"/>
    </visual>
    <collision>
      <origin rpy="0 0 0" xyz="0 0 0"/>
      <geometry>
        <box size="0.001 0.001 0.001"/>
      </geometry>
    </collision>
  </link>
  <transmission name="bl_caster_rotation_trans">
    <type>transmission_interface/SimpleTransmission</type>
    <joint name="bl_caster_rotation_joint"/>
    <actuator name="bl_caster_rotation_motor">
      <hardwareInterface>EffortJointInterface</hardwareInterface>
      <mechanicalReduction>-79.2380952381</mechanicalReduction>
    </actuator>
  </transmission>
  <joint name="bl_caster_r_wheel_joint" type="continuous">
    <axis xyz="0 1 0"/>
    <limit effort="100" velocity="100"/>
    <!-- alpha tested effort and velocity limits -->
    <safety_controller k_velocity="10"/>
    <dynamics damping="0.0" friction="0.0"/>
    <origin rpy="0 0 0" xyz="0 -0.0 0"/>
    <parent link="bl_caster_rotation_link"/>
    <child link="bl_caster_r_wheel_link"/>
  </joint>
  <link name="bl_caster_r_wheel_link">
    <inertial>
      <mass value="0.44036"/>
      <origin xyz="0 0 0"/>
      <inertia ixx="0.012411765597" ixy="-0.000711733678" ixz="0.00050272983" iyy="0.015218160428" iyz="-0.000004273467" izz="0.011763977943"/>
    </inertial>
    <visual>
      <origin rpy="1.57079632679 0 0" xyz="0 0 0"/>
      <geometry>
        <cylinder length="0.034" radius="0.074792"/>
      </geometry>
      <material name="IPA/LightGrey"/>
    </visual>
    <collision>
      <origin rpy="1.57079632679 0 0" xyz="0 0 0"/>
      <!-- rotation because cyl. geom primitive has symmetry axis in +x direction -->
      <geometry>
        <cylinder length="0.034" radius="0.074792"/>
      </geometry>
    </collision>
  </link>
  <gazebo reference="bl_caster_r_wheel_link">
    <mu1 value="100.0"/>
    <mu2 value="100.0"/>
    <kp value="1000000.0"/>
    <kd value="1.0"/>
    <material value="IPA/LightGrey"/>
  </gazebo>
  <transmission name="bl_caster_r_wheel_trans">
    <type>transmission_interface/SimpleTransmission</type>
    <joint name="bl_caster_r_wheel_joint"/>
    <actuator name="bl_caster_r_wheel_motor">
      <hardwareInterface>EffortJointInterface</hardwareInterface>
      <mechanicalReduction>-79.2380952381</mechanicalReduction>
    </actuator>
  </transmission>
  <gazebo reference="bl_caster_rotation_link">
    <material value="IPA/Metal"/>
  </gazebo>
  <joint name="br_caster_rotation_joint" type="continuous">
    <axis xyz="0 0 1"/>
    <limit effort="100" velocity="100"/>
    <!-- alpha tested velocity and effort limits -->
    <safety_controller k_velocity="10"/>
    <calibration rising="2.35619449019"/>
    <dynamics damping="0.0" friction="0.0"/>
    <origin rpy="0 0 0" xyz="-0.235 -0.185 0.075"/>
    <parent link="base_link"/>
    <child link="br_caster_rotation_link"/>
  </joint>
  <link name="br_caster_rotation_link">
    <inertial>
      <mass value="5.9"/>
      <origin xyz="0 0 0"/>
      <inertia ixx="0.04" ixy="-0.0007" ixz="0.0" iyy="0.02" iyz="-0.000004" izz="0.05"/>
    </inertial>
    <visual>
      <origin rpy="0 0 0" xyz="0 0 0"/>
      <geometry>
        <mesh filename="package://cob_description/meshes/cob3_base/caster.stl"/>
        <!--box size="0.001 0.001 0.001" /-->
      </geometry>
      <material name="IPA/LightGrey"/>
    </visual>
    <collision>
      <origin rpy="0 0 0" xyz="0 0 0"/>
      <geometry>
        <box size="0.001 0.001 0.001"/>
      </geometry>
    </collision>
  </link>
  <transmission name="br_caster_rotation_trans">
    <type>transmission_interface/SimpleTransmission</type>
    <joint name="br_caster_rotation_joint"/>
    <actuator name="br_caster_rotation_motor">
      <hardwareInterface>EffortJointInterface</hardwareInterface>
      <mechanicalReduction>-79.2380952381</mechanicalReduction>
    </actuator>
  </transmission>
  <joint name="br_caster_r_wheel_joint" type="continuous">
    <axis xyz="0 1 0"/>
    <limit effort="100" velocity="100"/>
    <!-- alpha tested effort and velocity limits -->
    <safety_controller k_velocity="10"/>
    <dynamics damping="0.0" friction="0.0"/>
    <origin rpy="0 0 0" xyz="0 -0.0 0"/>
    <parent link="br_caster_rotation_link"/>
    <child link="br_caster_r_wheel_link"/>
  </joint>
  <link name="br_caster_r_wheel_link">
    <inertial>
      <mass value="0.44036"/>
      <origin xyz="0 0 0"/>
      <inertia ixx="0.012411765597" ixy="-0.000711733678" ixz="0.00050272983" iyy="0.015218160428" iyz="-0.000004273467" izz="0.011763977943"/>
    </inertial>
    <visual>
      <origin rpy="1.57079632679 0 0" xyz="0 0 0"/>
      <geometry>
        <cylinder length="0.034" radius="0.074792"/>
      </geometry>
      <material name="IPA/LightGrey"/>
    </visual>
    <collision>
      <origin rpy="1.57079632679 0 0" xyz="0 0 0"/>
      <!-- rotation because cyl. geom primitive has symmetry axis in +x direction -->
      <geometry>
        <cylinder length="0.034" radius="0.074792"/>
      </geometry>
    </collision>
  </link>
  <gazebo reference="br_caster_r_wheel_link">
    <mu1 value="100.0"/>
    <mu2 value="100.0"/>
    <kp value="1000000.0"/>
    <kd value="1.0"/>
    <material value="IPA/LightGrey"/>
  </gazebo>
  <transmission name="br_caster_r_wheel_trans">
    <type>transmission_interface/SimpleTransmission</type>
    <joint name="br_caster_r_wheel_joint"/>
    <actuator name="br_caster_r_wheel_motor">
      <hardwareInterface>EffortJointInterface</hardwareInterface>
      <mechanicalReduction>-79.2380952381</mechanicalReduction>
    </actuator>
  </transmission>
  <gazebo reference="br_caster_rotation_link">
    <material value="IPA/Metal"/>
  </gazebo>
  <gazebo reference="base_link">
    <selfCollide>true</selfCollide>
    <sensor name="base_contact_sensor" type="contact">
      <contact>
        <collision>base_link_geom</collision>
      </contact>
      <plugin filename="libgazebo_ros_bumper.so" name="base_gazebo_ros_bumper_controller">
        <alwaysOn>true</alwaysOn>
        <updateRate>100.0</updateRate>
        <bumperTopicName>base_bumper</bumperTopicName>
        <frameName>world</frameName>
      </plugin>
    </sensor>
    <material>IPA/LightGrey</material>
  </gazebo>
  <gazebo>
    <plugin filename="libgazebo_ros_p3d.so" name="p3d_base_controller">
      <alwaysOn>true</alwaysOn>
      <updateRate>100.0</updateRate>
      <bodyName>base_link</bodyName>
      <topicName>base_pose_ground_truth</topicName>
      <gaussianNoise>0.01</gaussianNoise>
      <frameName>map</frameName>
      <xyzOffsets>25.7 25.7 0</xyzOffsets>
      <!-- initialize odometry for fake localization-->
      <rpyOffsets>0 0 0</rpyOffsets>
    </plugin>
    <canonicalBody>base_footprint</canonicalBody>
  </gazebo>
  <joint name="tray_joint" type="revolute">
    <origin rpy="2.3561 0.0 0.0" xyz="0.2406 0.19 0.732"/>
    <parent link="base_link"/>
    <child link="tray_link"/>
    <axis xyz="0 0 1"/>
    <calibration rising="-3.1415926"/>
    <dynamics damping="5.0" friction="0.5"/>
    <limit effort="100" lower="-3.31612" upper="0.2" velocity="5"/>
  </joint>
  <link name="tray_link">
    <inertial>
      <origin rpy="0 0 0" xyz="0 0 0"/>
      <mass value="0.1"/>
      <inertia ixx="0.01" ixy="0" ixz="0" iyy="0.01" iyz="0" izz="0.01"/>
    </inertial>
    <visual>
      <origin rpy="0 0 0" xyz="0 0 0"/>
      <geometry>
        <mesh filename="package://cob_description/meshes/cob3_tray/tray.stl"/>
      </geometry>
      <material name="IPA/DarkGrey"/>
    </visual>
    <collision>
      <origin rpy="0 0 0" xyz="0 0 0"/>
      <geometry>
        <mesh filename="package://cob_description/meshes/cob3_tray/tray_collision.stl"/>
      </geometry>
    </collision>
  </link>
  <joint name="tray_base_joint" type="fixed">
    <origin rpy="-2.3561 0 0" xyz="0 0 0"/>
    <parent link="tray_link"/>
    <child link="tray_base_link"/>
  </joint>
  <link name="tray_base_link"/>
  <joint name="tray_right_joint" type="fixed">
    <origin rpy="0 0 0" xyz="0.4 -0.3 0.1"/>
    <parent link="tray_base_link"/>
    <child link="tray_right_link"/>
  </joint>
  <link name="tray_right_link"/>
  <joint name="tray_left_joint" type="fixed">
    <origin rpy="0 0 0" xyz="0.4 0.05 0.1"/>
    <parent link="tray_base_link"/>
    <child link="tray_left_link"/>
  </joint>
  <link name="tray_left_link"/>
  <joint name="tray_phidgets_1_joint" type="fixed">
    <axis xyz="0 1 0"/>
    <origin rpy="0 0 -1.57079632679" xyz="-0.275 0 0.02"/>
    <parent link="tray_left_link"/>
    <child link="tray_phidgets_1_link"/>
  </joint>
  <link name="tray_phidgets_1_link"/>
  <gazebo reference="tray_phidgets_1_link">
    <sensor name="tray_phidgets_1" type="ray">
      <always_on>true</always_on>
      <update_rate>10</update_rate>
      <pose>0 0 0 0 0 0</pose>
      <visualize>false</visualize>
      <ray>
        <scan>
          <horizontal>
            <samples>10</samples>
            <resolution>1.0</resolution>
            <min_angle>-0.2</min_angle>
            <max_angle>0.2</max_angle>
          </horizontal>
        </scan>
        <range>
          <min>0.01</min>
          <!-- real value from sensor datasheet is 0.04m -->
          <max>0.4</max>
          <!-- real value from sensor datasheet is 0.30m -->
          <resolution>0.005</resolution>
        </range>
      </ray>
      <plugin filename="libgazebo_ros_laser.so" name="gazebo_ros_tray_phidgets_1_controller">
        <gaussianNoise>0.005</gaussianNoise>
        <alwaysOn>true</alwaysOn>
        <updateRate>10</updateRate>
        <topicName>/tray_sensors/range_1_sim</topicName>
        <frameName>/tray_phidgets_1_link</frameName>
        <hokuyoMinIntensity>101.0</hokuyoMinIntensity>
      </plugin>
    </sensor>
    <material>IPA/LightGrey</material>
  </gazebo>
  <joint name="tray_phidgets_2_joint" type="fixed">
    <axis xyz="0 1 0"/>
    <origin rpy="0 0 -1.57079632679" xyz="-0.2 0 0.02"/>
    <parent link="tray_left_link"/>
    <child link="tray_phidgets_2_link"/>
  </joint>
  <link name="tray_phidgets_2_link"/>
  <gazebo reference="tray_phidgets_2_link">
    <sensor name="tray_phidgets_2" type="ray">
      <always_on>true</always_on>
      <update_rate>10</update_rate>
      <pose>0 0 0 0 0 0</pose>
      <visualize>false</visualize>
      <ray>
        <scan>
          <horizontal>
            <samples>10</samples>
            <resolution>1.0</resolution>
            <min_angle>-0.2</min_angle>
            <max_angle>0.2</max_angle>
          </horizontal>
        </scan>
        <range>
          <min>0.01</min>
          <!-- real value from sensor datasheet is 0.04m -->
          <max>0.4</max>
          <!-- real value from sensor datasheet is 0.30m -->
          <resolution>0.005</resolution>
        </range>
      </ray>
      <plugin filename="libgazebo_ros_laser.so" name="gazebo_ros_tray_phidgets_2_controller">
        <gaussianNoise>0.005</gaussianNoise>
        <alwaysOn>true</alwaysOn>
        <updateRate>10</updateRate>
        <topicName>/tray_sensors/range_2_sim</topicName>
        <frameName>/tray_phidgets_2_link</frameName>
        <hokuyoMinIntensity>101.0</hokuyoMinIntensity>
      </plugin>
    </sensor>
    <material>IPA/LightGrey</material>
  </gazebo>
  <joint name="tray_phidgets_3_joint" type="fixed">
    <axis xyz="0 1 0"/>
    <origin rpy="0 0 -1.57079632679" xyz="-0.125 0 0.02"/>
    <parent link="tray_left_link"/>
    <child link="tray_phidgets_3_link"/>
  </joint>
  <link name="tray_phidgets_3_link"/>
  <gazebo reference="tray_phidgets_3_link">
    <sensor name="tray_phidgets_3" type="ray">
      <always_on>true</always_on>
      <update_rate>10</update_rate>
      <pose>0 0 0 0 0 0</pose>
      <visualize>false</visualize>
      <ray>
        <scan>
          <horizontal>
            <samples>10</samples>
            <resolution>1.0</resolution>
            <min_angle>-0.2</min_angle>
            <max_angle>0.2</max_angle>
          </horizontal>
        </scan>
        <range>
          <min>0.01</min>
          <!-- real value from sensor datasheet is 0.04m -->
          <max>0.4</max>
          <!-- real value from sensor datasheet is 0.30m -->
          <resolution>0.005</resolution>
        </range>
      </ray>
      <plugin filename="libgazebo_ros_laser.so" name="gazebo_ros_tray_phidgets_3_controller">
        <gaussianNoise>0.005</gaussianNoise>
        <alwaysOn>true</alwaysOn>
        <updateRate>10</updateRate>
        <topicName>/tray_sensors/range_3_sim</topicName>
        <frameName>/tray_phidgets_3_link</frameName>
        <hokuyoMinIntensity>101.0</hokuyoMinIntensity>
      </plugin>
    </sensor>
    <material>IPA/LightGrey</material>
  </gazebo>
  <joint name="tray_phidgets_4_joint" type="fixed">
    <axis xyz="0 1 0"/>
    <origin rpy="0 0 -1.57079632679" xyz="-0.05 0 0.02"/>
    <parent link="tray_left_link"/>
    <child link="tray_phidgets_4_link"/>
  </joint>
  <link name="tray_phidgets_4_link"/>
  <gazebo reference="tray_phidgets_4_link">
    <sensor name="tray_phidgets_4" type="ray">
      <always_on>true</always_on>
      <update_rate>10</update_rate>
      <pose>0 0 0 0 0 0</pose>
      <visualize>false</visualize>
      <ray>
        <scan>
          <horizontal>
            <samples>10</samples>
            <resolution>1.0</resolution>
            <min_angle>-0.2</min_angle>
            <max_angle>0.2</max_angle>
          </horizontal>
        </scan>
        <range>
          <min>0.01</min>
          <!-- real value from sensor datasheet is 0.04m -->
          <max>0.4</max>
          <!-- real value from sensor datasheet is 0.30m -->
          <resolution>0.005</resolution>
        </range>
      </ray>
      <plugin filename="libgazebo_ros_laser.so" name="gazebo_ros_tray_phidgets_4_controller">
        <gaussianNoise>0.005</gaussianNoise>
        <alwaysOn>true</alwaysOn>
        <updateRate>10</updateRate>
        <topicName>/tray_sensors/range_4_sim</topicName>
        <frameName>/tray_phidgets_4_link</frameName>
        <hokuyoMinIntensity>101.0</hokuyoMinIntensity>
      </plugin>
    </sensor>
    <material>IPA/LightGrey</material>
  </gazebo>
  <gazebo reference="tray_link">
    <material>IPA/DarkGrey</material>
    <turnGravityOff>false</turnGravityOff>
  </gazebo>
  <transmission name="tray_trans">
    <type>transmission_interface/SimpleTransmission</type>
    <joint name="tray_joint"/>
    <actuator name="tray_motor">
      <hardwareInterface>EffortJointInterface</hardwareInterface>
      <mechanicalReduction>1</mechanicalReduction>
    </actuator>
  </transmission>
  <joint name="torso_base_joint" type="fixed">
    <origin rpy="3.1415926 0.0 0.0" xyz="0.155 0.0 0.892"/>
    <parent link="base_link"/>
    <child link="torso_base_link"/>
  </joint>
  <link name="torso_base_link">
    <inertial>
      <origin rpy="0 0 0" xyz="0 0 0"/>
      <mass value="0.01"/>
      <inertia ixx="1" ixy="0" ixz="0" iyy="1" iyz="0" izz="1"/>
    </inertial>
  </link>
  <joint name="torso_lower_neck_pan_joint" type="revolute">
    <origin rpy="0 0 0" xyz="0 0 0"/>
    <parent link="torso_base_link"/>
    <child link="torso_lower_neck_pan_link"/>
    <axis xyz="0 0 1"/>
    <calibration rising="0.0"/>
    <dynamics damping="25.0" friction="10.0"/>
    <limit effort="200" lower="-0.1" upper="0.1" velocity="0.5"/>
  </joint>
  <link name="torso_lower_neck_pan_link">
    <inertial>
      <origin rpy="0 0 0" xyz="0 0 0"/>
      <mass value="1.0"/>
      <inertia ixx="0.200549" ixy="0.001322" ixz="-0.000000" iyy="0.123664" iyz="-0.000000" izz="0.104101"/>
    </inertial>
    <visual>
      <origin rpy="0 0 0" xyz="0 0 0.005"/>
      <geometry>
        <box size="0.01 0.01 0.01"/>
      </geometry>
      <material name="IPA/LightGrey"/>
    </visual>
    <collision>
      <origin rpy="0 0 0" xyz="0 0 0.0005"/>
      <geometry>
        <box size="0.001 0.001 0.001"/>
      </geometry>
    </collision>
  </link>
  <joint name="torso_lower_neck_tilt_joint" type="revolute">
    <origin rpy="1.57079632679 0 0" xyz="0 0 0"/>
    <parent link="torso_lower_neck_pan_link"/>
    <child link="torso_lower_neck_tilt_link"/>
    <axis xyz="0 0 1"/>
    <dynamics damping="25.0" friction="10.0"/>
    <calibration rising="0.0"/>
    <limit effort="200" lower="-0.26" upper="0.25" velocity="0.5"/>
  </joint>
  <link name="torso_lower_neck_tilt_link">
    <inertial>
      <origin rpy="0 0 0" xyz="0 0 0"/>
      <mass value="6.209720"/>
      <inertia ixx="0.171118" ixy="0.002544" ixz="-0.000000" iyy="0.083077" iyz="0.000000" izz="0.120948"/>
    </inertial>
    <visual>
      <origin rpy="0 0 0" xyz="0 0 0"/>
      <geometry>
        <mesh filename="package://cob_description/meshes/cob3_torso/lower_neck.stl"/>
      </geometry>
      <material name="IPA/LightGrey"/>
    </visual>
    <collision>
      <origin rpy="0 0 0" xyz="0 0 0"/>
      <geometry>
        <mesh filename="package://cob_description/meshes/cob3_torso/lower_neck_collision.stl"/>
      </geometry>
    </collision>
  </link>
  <joint name="torso_upper_neck_pan_joint" type="revolute">
    <origin rpy="-1.57079632679 0 0" xyz="0 -0.237 0"/>
    <parent link="torso_lower_neck_tilt_link"/>
    <child link="torso_upper_neck_pan_link"/>
    <axis xyz="0 0 1"/>
    <dynamics damping="25.0" friction="10.0"/>
    <calibration rising="0.0"/>
    <limit effort="200" lower="-0.2" upper="0.2" velocity="0.5"/>
  </joint>
  <link name="torso_upper_neck_pan_link">
    <inertial>
      <origin rpy="0 0 0" xyz="0 0 0"/>
      <mass value="1.0"/>
      <inertia ixx="0.01" ixy="0" ixz="0" iyy="0.01" iyz="0" izz="0.01"/>
    </inertial>
    <visual>
      <origin rpy="0 0 0" xyz="0 0 0.005"/>
      <geometry>
        <box size="0.01 0.01 0.01"/>
      </geometry>
      <material name="IPA/LightGrey"/>
    </visual>
    <collision>
      <origin rpy="0 0 0" xyz="0 0 0.0005"/>
      <geometry>
        <box size="0.001 0.001 0.001"/>
      </geometry>
    </collision>
  </link>
  <joint name="torso_upper_neck_tilt_joint" type="revolute">
    <origin rpy="1.57079632679 0 0" xyz="0 0 0"/>
    <parent link="torso_upper_neck_pan_link"/>
    <child link="torso_upper_neck_tilt_link"/>
    <axis xyz="0 0 1"/>
    <dynamics damping="25.0" friction="10.0"/>
    <calibration rising="0.0"/>
    <limit effort="200" lower="-0.21" upper="0.3" velocity="0.5"/>
  </joint>
  <link name="torso_upper_neck_tilt_link">
    <inertial>
      <origin rpy="0 0 0" xyz="0 0 0"/>
      <mass value="6.744238"/>
      <inertia ixx="0.01" ixy="0" ixz="0" iyy="0.01" iyz="0" izz="0.01"/>
    </inertial>
    <visual>
      <origin rpy="0 0 0" xyz="0 0 0"/>
      <geometry>
        <mesh filename="package://cob_description/meshes/cob3_torso/upper_neck.stl"/>
      </geometry>
      <material name="IPA/LightGrey"/>
    </visual>
    <collision>
      <origin rpy="0 0 0" xyz="0 0 0"/>
      <geometry>
        <mesh filename="package://cob_description/meshes/cob3_torso/upper_neck.stl"/>
      </geometry>
    </collision>
  </link>
  <joint name="head_cover_joint" type="fixed">
    <origin rpy="0 0 0" xyz="0 0 0"/>
    <parent link="torso_upper_neck_tilt_link"/>
    <child link="head_cover_link"/>
  </joint>
  <link name="head_cover_link">
    <inertial>
      <origin rpy="0 0 0" xyz="0 0 0"/>
      <mass value="0.5"/>
      <inertia ixx="0.01" ixy="0" ixz="0" iyy="0.01" iyz="0" izz="0.01"/>
    </inertial>
    <visual>
      <origin rpy="0 0 0" xyz="0 0 0"/>
      <geometry>
        <mesh filename="package://cob_description/meshes/cob3_torso/head_cover.stl"/>
      </geometry>
      <material name="IPA/Black"/>
    </visual>
    <collision>
      <origin rpy="0 0 0" xyz="0 0 0"/>
      <geometry>
        <mesh filename="package://cob_description/meshes/cob3_torso/head_cover_collision.stl"/>
      </geometry>
    </collision>
  </link>
  <gazebo reference="torso_lower_neck_pan_link">
    <material>IPA/LightGrey</material>
    <turnGravityOff>false</turnGravityOff>
  </gazebo>
  <gazebo reference="torso_lower_neck_tilt_link">
    <material>IPA/LightGrey</material>
    <turnGravityOff>false</turnGravityOff>
  </gazebo>
  <gazebo reference="torso_upper_neck_pan_link">
    <material>IPA/LightGrey</material>
    <turnGravityOff>false</turnGravityOff>
  </gazebo>
  <gazebo reference="torso_upper_neck_tilt_link">
    <material>IPA/LightGrey</material>
    <turnGravityOff>false</turnGravityOff>
  </gazebo>
  <gazebo reference="head_cover_link">
    <material>IPA/Black</material>
    <turnGravityOff>false</turnGravityOff>
  </gazebo>
  <transmission name="torso_lower_neck_pan_trans">
    <type>transmission_interface/SimpleTransmission</type>
    <joint name="torso_lower_neck_pan_joint"/>
    <actuator name="torso_lower_neck_pan_motor">
      <hardwareInterface>EffortJointInterface</hardwareInterface>
      <mechanicalReduction>1</mechanicalReduction>
    </actuator>
  </transmission>
  <transmission name="torso_lower_neck_tilt_trans">
    <type>transmission_interface/SimpleTransmission</type>
    <joint name="torso_lower_neck_tilt_joint"/>
    <actuator name="torso_lower_neck_tilt_motor">
      <hardwareInterface>EffortJointInterface</hardwareInterface>
      <mechanicalReduction>1</mechanicalReduction>
    </actuator>
  </transmission>
  <transmission name="torso_upper_neck_pan_trans">
    <type>transmission_interface/SimpleTransmission</type>
    <joint name="torso_upper_neck_pan_joint"/>
    <actuator name="torso_upper_neck_pan_motor">
      <hardwareInterface>EffortJointInterface</hardwareInterface>
      <mechanicalReduction>1</mechanicalReduction>
    </actuator>
  </transmission>
  <transmission name="torso_upper_neck_tilt_trans">
    <type>transmission_interface/SimpleTransmission</type>
    <joint name="torso_upper_neck_tilt_joint"/>
    <actuator name="torso_upper_neck_tilt_motor">
      <hardwareInterface>EffortJointInterface</hardwareInterface>
      <mechanicalReduction>1</mechanicalReduction>
    </actuator>
  </transmission>
  <joint name="arm_0_joint" type="fixed">
    <origin rpy="0.7854 0.0 -0.2618" xyz="-0.015982 -0.080992 0.875995"/>
    <parent link="base_link"/>
    <child link="arm_0_link"/>
  </joint>
  <link name="arm_0_link">
    <inertial>
      <origin rpy="0 0 0" xyz="0 0 -0.07"/>
      <mass value="1.0"/>
      <inertia ixx="0.01" ixy="0" ixz="0" iyy="0.01" iyz="0" izz="0.01"/>
    </inertial>
    <visual>
      <origin rpy="0 0 0" xyz="0 0 -0.07"/>
      <geometry>
        <cylinder length="0.14" radius="0.060"/>
      </geometry>
      <material name="IPA/Orange"/>
    </visual>
    <collision>
      <origin rpy="0 0 0" xyz="0 0 -0.07"/>
      <geometry>
        <cylinder length="0.14" radius="0.060"/>
      </geometry>
    </collision>
  </link>
  <joint name="arm_1_joint" type="revolute">
    <origin rpy="0 0 -2.8407" xyz="0 0 0.0"/>
    <parent link="arm_0_link"/>
    <child link="arm_1_link"/>
    <axis xyz="0 0 1"/>
    <dynamics damping="10"/>
    <limit effort="200" lower="-2.9670" upper="2.9670" velocity="1.9634"/>
    <safety_controller k_position="20" k_velocity="50" soft_lower_limit="-2.957" soft_upper_limit="2.957"/>
  </joint>
  <link name="arm_1_link">
    <inertial>
      <origin rpy="0 0 0" xyz="0 0 0"/>
      <!--mass value="5.9907"/-->
      <mass value="2.0"/>
      <inertia ixx="0.01" ixy="0" ixz="0" iyy="0.01" iyz="0" izz="0.01"/>
    </inertial>
    <visual>
      <origin rpy="0 0 0" xyz="0 0 0"/>
      <geometry>
        <mesh filename="package://cob_description/meshes/lbr/joint_1.stl"/>
      </geometry>
      <material name="IPA/Orange"/>
    </visual>
    <collision>
      <origin rpy="0 0 0" xyz="0 0 0"/>
      <geometry>
        <mesh filename="package://cob_description/meshes/lbr/joint_1_collision.stl"/>
      </geometry>
    </collision>
  </link>
  <joint name="arm_2_joint" type="revolute">
    <origin rpy="1.57079632679 0 0" xyz="0 -0.002 0.1915"/>
    <parent link="arm_1_link"/>
    <child link="arm_2_link"/>
    <axis xyz="0 0 1"/>
    <dynamics damping="10"/>
    <limit effort="200" lower="-2.0943" upper="2.0943" velocity="1.9634"/>
    <safety_controller k_position="20" k_velocity="50" soft_lower_limit="-2.0843" soft_upper_limit="2.0843"/>
  </joint>
  <link name="arm_2_link">
    <inertial>
      <origin rpy="0 0 0" xyz="0 0 0"/>
      <!--mass value="5.734939"/-->
      <mass value="2.0"/>
      <inertia ixx="0.03" ixy="0" ixz="0" iyy="0.03" iyz="0" izz="0.03"/>
    </inertial>
    <visual>
      <origin rpy="0 0 0" xyz="0 0 0"/>
      <geometry>
        <mesh filename="package://cob_description/meshes/lbr/joint_2.stl"/>
      </geometry>
      <material name="IPA/Orange"/>
    </visual>
    <collision>
      <origin rpy="0 0 0" xyz="0 0 0"/>
      <geometry>
        <mesh filename="package://cob_description/meshes/lbr/joint_2_collision.stl"/>
      </geometry>
    </collision>
  </link>
  <joint name="arm_3_joint" type="revolute">
    <origin rpy="-1.57079632679 0 0" xyz="0 0.2085 0"/>
    <parent link="arm_2_link"/>
    <child link="arm_3_link"/>
    <axis xyz="0 0 1"/>
    <dynamics damping="5"/>
    <limit effort="100" lower="-2.9670" upper="2.9670" velocity="1.9634"/>
    <safety_controller k_position="20" k_velocity="25" soft_lower_limit="-2.957" soft_upper_limit="2.957"/>
  </joint>
  <link name="arm_3_link">
    <inertial>
      <origin rpy="0 0 0" xyz="0 0 0"/>
      <!--mass value="4.214668"/-->
      <mass value="2.0"/>
      <inertia ixx="0.03" ixy="0" ixz="0" iyy="0.03" iyz="0" izz="0.03"/>
    </inertial>
    <visual>
      <origin rpy="0 0 0" xyz="0 0 0"/>
      <geometry>
        <mesh filename="package://cob_description/meshes/lbr/joint_3.stl"/>
      </geometry>
      <material name="IPA/Orange"/>
    </visual>
    <collision>
      <origin rpy="0 0 0" xyz="0 0 0"/>
      <geometry>
        <mesh filename="package://cob_description/meshes/lbr/joint_3_collision.stl"/>
      </geometry>
    </collision>
  </link>
  <joint name="arm_4_joint" type="revolute">
    <origin rpy="-1.57079632679 0 0" xyz="0 0.002 0.1915"/>
    <parent link="arm_3_link"/>
    <child link="arm_4_link"/>
    <axis xyz="0 0 1"/>
    <dynamics damping="5"/>
    <limit effort="100" lower="-2.0943" upper="2.0943" velocity="1.9634"/>
    <!--limit effort="176" velocity="0.4189" upper="2.0943951" lower="-2.0943951"/-->
    <safety_controller k_position="20" k_velocity="25" soft_lower_limit="-2.0843" soft_upper_limit="2.0843"/>
  </joint>
  <link name="arm_4_link">
    <inertial>
      <origin rpy="0 0 0" xyz="0 0 0"/>
      <!--mass value="3.669819"/-->
      <mass value="2.0"/>
      <inertia ixx="0.03" ixy="0" ixz="0" iyy="0.03" iyz="0" izz="0.03"/>
    </inertial>
    <visual>
      <origin rpy="0 0 0" xyz="0 0 0"/>
      <geometry>
        <mesh filename="package://cob_description/meshes/lbr/joint_4.stl"/>
      </geometry>
      <material name="IPA/Orange"/>
    </visual>
    <collision>
      <origin rpy="0 0 0" xyz="0 0 0"/>
      <geometry>
        <mesh filename="package://cob_description/meshes/lbr/joint_4_collision.stl"/>
      </geometry>
    </collision>
  </link>
  <joint name="arm_5_joint" type="revolute">
    <origin rpy="1.57079632679 0 0" xyz="0 -0.2085 0"/>
    <parent link="arm_4_link"/>
    <child link="arm_5_link"/>
    <axis xyz="0 0 1"/>
    <dynamics damping="5"/>
    <limit effort="100" lower="-2.9670" upper="2.9670" velocity="1.9634"/>
    <safety_controller k_position="20" k_velocity="25" soft_lower_limit="-2.957" soft_upper_limit="2.957"/>
  </joint>
  <link name="arm_5_link">
    <inertial>
      <origin rpy="0 0 0" xyz="0 0 0"/>
      <mass value="2.313272"/>
      <inertia ixx="0.03" ixy="0" ixz="0" iyy="0.03" iyz="0" izz="0.03"/>
    </inertial>
    <visual>
      <origin rpy="0 0 0" xyz="0 0 0"/>
      <geometry>
        <mesh filename="package://cob_description/meshes/lbr/joint_5.stl"/>
      </geometry>
      <material name="IPA/Orange"/>
    </visual>
    <collision>
      <origin rpy="0 0 0" xyz="0 0 0"/>
      <geometry>
        <mesh filename="package://cob_description/meshes/lbr/joint_5_collision.stl"/>
      </geometry>
    </collision>
  </link>
  <joint name="arm_6_joint" type="revolute">
    <origin rpy="1.57079632679 0 0" xyz="0 0.046 0.1815"/>
    <parent link="arm_5_link"/>
    <child link="arm_6_link"/>
    <axis xyz="0 0 1"/>
    <dynamics damping="5"/>
    <limit effort="30" lower="-2.0943951" upper="2.0943951" velocity="1.9634"/>
    <!--limit effort="20.1" velocity="0.4363" upper="2.0943951" lower="-2.0943951" /-->
    <safety_controller k_position="20" k_velocity="25" soft_lower_limit="-2.0843951" soft_upper_limit="2.0843951"/>
  </joint>
  <link name="arm_6_link">
    <inertial>
      <origin rpy="0 0 0" xyz="0 0 0"/>
      <mass value="2.057856"/>
      <inertia ixx="0.01" ixy="0" ixz="0" iyy="0.01" iyz="0" izz="0.01"/>
    </inertial>
    <visual>
      <origin rpy="0 0 0" xyz="0 0 0"/>
      <geometry>
        <mesh filename="package://cob_description/meshes/lbr/joint_6.stl"/>
      </geometry>
      <material name="IPA/Orange"/>
    </visual>
    <collision>
      <origin rpy="0 0 0" xyz="0 0 0"/>
      <geometry>
        <mesh filename="package://cob_description/meshes/lbr/joint_6_collision.stl"/>
      </geometry>
    </collision>
  </link>
  <joint name="arm_7_joint" type="revolute">
    <origin rpy="-1.57079632679 0 0" xyz="0 0.057 0.0455"/>
    <parent link="arm_6_link"/>
    <child link="arm_7_link"/>
    <axis xyz="0 0 1"/>
    <dynamics damping="5"/>
    <limit effort="30" lower="-2.9670" upper="2.9670" velocity="1.9634"/>
    <!--limit effort="20.1" velocity="0.4363" upper="2.0943951" lower="-2.0943951" /-->
    <safety_controller k_position="20" k_velocity="25" soft_lower_limit="-2.957" soft_upper_limit="2.957"/>
  </joint>
  <link name="arm_7_link">
    <inertial>
      <origin rpy="0 0 0" xyz="0 0 0"/>
      <mass value="1.120198"/>
      <inertia ixx="0.01" ixy="0" ixz="0" iyy="0.01" iyz="0" izz="0.01"/>
    </inertial>
    <visual>
      <origin rpy="0 0 0" xyz="0 0 0"/>
      <geometry>
        <mesh filename="package://cob_description/meshes/lbr/joint_7.stl"/>
      </geometry>
      <material name="IPA/Orange"/>
    </visual>
    <collision>
      <origin rpy="0 0 0" xyz="0 0 0"/>
      <geometry>
        <mesh filename="package://cob_description/meshes/lbr/joint_7_collision.stl"/>
      </geometry>
    </collision>
  </link>
  <gazebo reference="arm_0_link">
    <material>IPA/Orange</material>
    <turnGravityOff>true</turnGravityOff>
  </gazebo>
  <gazebo reference="arm_1_link">
    <material>IPA/Orange</material>
    <turnGravityOff>true</turnGravityOff>
  </gazebo>
  <gazebo reference="arm_2_link">
    <material>IPA/Orange</material>
    <turnGravityOff>true</turnGravityOff>
  </gazebo>
  <gazebo reference="arm_3_link">
    <material>IPA/Orange</material>
    <turnGravityOff>true</turnGravityOff>
  </gazebo>
  <gazebo reference="arm_4_link">
    <material>IPA/Orange</material>
    <turnGravityOff>true</turnGravityOff>
  </gazebo>
  <gazebo reference="arm_5_link">
    <material>IPA/Orange</material>
    <turnGravityOff>true</turnGravityOff>
  </gazebo>
  <gazebo reference="arm_6_link">
    <material>IPA/Orange</material>
    <turnGravityOff>true</turnGravityOff>
  </gazebo>
  <gazebo reference="arm_7_link">
    <material>IPA/Orange</material>
    <turnGravityOff>true</turnGravityOff>
  </gazebo>
  <transmission name="arm_1_trans">
    <type>transmission_interface/SimpleTransmission</type>
    <joint name="arm_1_joint"/>
    <actuator name="arm_1_motor">
      <hardwareInterface>EffortJointInterface</hardwareInterface>
      <mechanicalReduction>1</mechanicalReduction>
    </actuator>
  </transmission>
  <transmission name="arm_2_trans">
    <type>transmission_interface/SimpleTransmission</type>
    <joint name="arm_2_joint"/>
    <actuator name="arm_2_motor">
      <hardwareInterface>EffortJointInterface</hardwareInterface>
      <mechanicalReduction>1</mechanicalReduction>
    </actuator>
  </transmission>
  <transmission name="arm_3_trans">
    <type>transmission_interface/SimpleTransmission</type>
    <joint name="arm_3_joint"/>
    <actuator name="arm_3_motor">
      <hardwareInterface>EffortJointInterface</hardwareInterface>
      <mechanicalReduction>1</mechanicalReduction>
    </actuator>
  </transmission>
  <transmission name="arm_4_trans">
    <type>transmission_interface/SimpleTransmission</type>
    <joint name="arm_4_joint"/>
    <actuator name="arm_4_motor">
      <hardwareInterface>EffortJointInterface</hardwareInterface>
      <mechanicalReduction>1</mechanicalReduction>
    </actuator>
  </transmission>
  <transmission name="arm_5_trans">
    <type>transmission_interface/SimpleTransmission</type>
    <joint name="arm_5_joint"/>
    <actuator name="arm_5_motor">
      <hardwareInterface>EffortJointInterface</hardwareInterface>
      <mechanicalReduction>1</mechanicalReduction>
    </actuator>
  </transmission>
  <transmission name="arm_6_trans">
    <type>transmission_interface/SimpleTransmission</type>
    <joint name="arm_6_joint"/>
    <actuator name="arm_6_motor">
      <hardwareInterface>EffortJointInterface</hardwareInterface>
      <mechanicalReduction>1</mechanicalReduction>
    </actuator>
  </transmission>
  <transmission name="arm_7_trans">
    <type>transmission_interface/SimpleTransmission</type>
    <joint name="arm_7_joint"/>
    <actuator name="arm_7_motor">
      <hardwareInterface>EffortJointInterface</hardwareInterface>
      <mechanicalReduction>1</mechanicalReduction>
    </actuator>
  </transmission>
  <joint name="head_base_joint" type="fixed">
    <origin rpy="3.1415926 3.1415926 3.14159265359" xyz="0.0 -0.154 0.0"/>
    <parent link="torso_upper_neck_tilt_link"/>
    <child link="head_base_link"/>
  </joint>
  <link name="head_base_link">
    <inertial>
      <origin rpy="0 0 0" xyz="0 0 0"/>
      <mass value="0.5"/>
      <inertia ixx="0.01" ixy="0" ixz="0" iyy="0.01" iyz="0" izz="0.01"/>
    </inertial>
  </link>
  <joint name="head_axis_joint" type="revolute">
    <origin rpy="0 0 0" xyz="0 0 0"/>
    <parent link="head_base_link"/>
    <child link="head_axis_link"/>
    <axis xyz="0 0 1"/>
    <dynamics damping="0.1"/>
    <calibration rising="-0.1"/>
    <limit effort="100" lower="-3.2" upper="0.25" velocity="1.4"/>
  </joint>
  <link name="head_axis_link">
    <inertial>
      <origin rpy="0 0 0" xyz="0 0 0"/>
      <mass value="0.1"/>
      <inertia ixx="0.0001" ixy="0" ixz="0" iyy="0.0001" iyz="0" izz="0.0001"/>
    </inertial>
    <visual>
      <origin rpy="0 0 0" xyz="0 0 0"/>
      <geometry>
        <box size="0.01 0.01 0.12"/>
      </geometry>
      <material name="IPA/LightGrey"/>
    </visual>
    <collision>
      <origin rpy="0 0 0" xyz="0 0 0"/>
      <geometry>
        <box size="0.01 0.01 0.12"/>
      </geometry>
    </collision>
  </link>
  <joint name="head_cam_reference_joint" type="fixed">
    <origin rpy="0.0 1.57079633 0.0" xyz="0.0 0.0 -0.06"/>
    <parent link="head_axis_link"/>
    <child link="head_cam_reference_link"/>
  </joint>
  <link name="head_cam_reference_link">
    <inertial>
      <origin rpy="0 0 0" xyz="0 0 0"/>
      <mass value="0.5"/>
      <inertia ixx="0.01" ixy="0" ixz="0" iyy="0.01" iyz="0" izz="0.01"/>
    </inertial>
  </link>
  <joint name="head_color_camera_l_joint" type="fixed">
    <origin rpy="0.0 0.0 0.0" xyz="0.0 0.0 0.0"/>
    <parent link="head_cam_reference_link"/>
    <child link="head_color_camera_l_link"/>
  </joint>
  <link name="head_color_camera_l_link">
    <inertial>
      <mass value="0.01"/>
      <origin rpy="0 0 0" xyz="0 0 0"/>
      <inertia ixx="0.0001" ixy="0" ixz="0" iyy="0.0001" iyz="0" izz="0.0001"/>
    </inertial>
    <visual>
      <origin rpy="0 0 0" xyz="0 0 0"/>
      <geometry>
        <cylinder length="0.03" radius="0.01"/>
      </geometry>
      <material name="IPA/LightGrey"/>
    </visual>
    <collision>
      <origin rpy="0 0 0" xyz="0 0 0"/>
      <geometry>
        <cylinder length="0.03" radius="0.01"/>
      </geometry>
    </collision>
  </link>
  <joint name="head_color_camera_l_frame_joint" type="fixed">
    <origin rpy="1.57079632679 -1.57079632679 0" xyz="0 0 0"/>
    <parent link="head_color_camera_l_link"/>
    <child link="head_color_camera_l_frame"/>
  </joint>
  <link name="head_color_camera_l_frame"/>
  <gazebo reference="head_color_camera_l_frame">
    <sensor name="head_color_camera_l_sensor" type="camera">
      <always_on>true</always_on>
      <update_rate>10.0</update_rate>
      <camera name="head_color_camera_l_sensor">
        <horizontal_fov>0.58</horizontal_fov>
        <image>
          <format>R8G8B8</format>
          <width>1360</width>
          <height>1024</height>
        </image>
        <clip>
          <near>0.1</near>
          <far>100</far>
        </clip>
      </camera>
      <plugin filename="libgazebo_ros_camera.so" name="head_color_camera_l_controller">
        <alwaysOn>true</alwaysOn>
        <updateRate>10.0</updateRate>
        <cameraName>head_color_camera_l_sensor</cameraName>
        <frameName>/head_color_camera_l_link</frameName>
        <topicName>stereo/left_image_data</topicName>
        <imageTopicName>/stereo/left/image_raw</imageTopicName>
        <cameraInfoTopicName>/stereo/left/camera_info</cameraInfoTopicName>
        <pollServiceName>/head_color_camera_l/request_image</pollServiceName>
        <CxPrime>697.69</CxPrime>
        <Cx>697.69</Cx>
        <Cy>530.51</Cy>
        <focalLength>2278.722731</focalLength>
        <!-- focal_length = width_ / (2.0 * tan( HFOV/2.0 )) -->
        <hackBaseline>0.0</hackBaseline>
        <distortionK1>0.0</distortionK1>
        <distortionK2>0.0</distortionK2>
        <distortionK3>0.0</distortionK3>
        <distortionT1>0.0</distortionT1>
        <distortionT2>0.0</distortionT2>
      </plugin>
    </sensor>
    <material value="IPA/LightGrey"/>
    <turnGravityOff>true</turnGravityOff>
  </gazebo>
  <joint name="head_color_camera_r_joint" type="fixed">
    <origin rpy="0.0 0.0 0.0" xyz="-0.12075932 0.0 0.0"/>
    <parent link="head_cam_reference_link"/>
    <child link="head_color_camera_r_link"/>
  </joint>
  <link name="head_color_camera_r_link">
    <inertial>
      <mass value="0.01"/>
      <origin rpy="0 0 0" xyz="0 0 0"/>
      <inertia ixx="0.0001" ixy="0" ixz="0" iyy="0.0001" iyz="0" izz="0.0001"/>
    </inertial>
    <visual>
      <origin rpy="0 0 0" xyz="0 0 0"/>
      <geometry>
        <cylinder length="0.03" radius="0.01"/>
      </geometry>
      <material name="IPA/LightGrey"/>
    </visual>
    <collision>
      <origin rpy="0 0 0" xyz="0 0 0"/>
      <geometry>
        <cylinder length="0.03" radius="0.01"/>
      </geometry>
    </collision>
  </link>
  <joint name="head_color_camera_r_frame_joint" type="fixed">
    <origin rpy="1.57079632679 -1.57079632679 0" xyz="0 0 0"/>
    <parent link="head_color_camera_r_link"/>
    <child link="head_color_camera_r_frame"/>
  </joint>
  <link name="head_color_camera_r_frame"/>
  <gazebo reference="head_color_camera_r_frame">
    <sensor name="head_color_camera_r_sensor" type="camera">
      <always_on>true</always_on>
      <update_rate>10.0</update_rate>
      <camera name="head_color_camera_r_sensor">
        <horizontal_fov>0.58</horizontal_fov>
        <image>
          <format>R8G8B8</format>
          <width>1360</width>
          <height>1024</height>
        </image>
        <clip>
          <near>0.1</near>
          <far>100</far>
        </clip>
      </camera>
      <plugin filename="libgazebo_ros_camera.so" name="head_color_camera_r_controller">
        <alwaysOn>true</alwaysOn>
        <updateRate>10.0</updateRate>
        <cameraName>head_color_camera_r_sensor</cameraName>
        <frameName>/head_color_camera_r_link</frameName>
        <topicName>stereo/right_image_data</topicName>
        <imageTopicName>/stereo/right/image_raw</imageTopicName>
        <cameraInfoTopicName>/stereo/right/camera_info</cameraInfoTopicName>
        <pollServiceName>/head_color_camera_r/request_image</pollServiceName>
        <CxPrime>697.69</CxPrime>
        <Cx>697.69</Cx>
        <Cy>530.51</Cy>
        <focalLength>2278.722731</focalLength>
        <!-- focal_length = width_ / (2.0 * tan( HFOV/2.0 )) -->
        <hackBaseline>0.0</hackBaseline>
        <distortionK1>0.0</distortionK1>
        <distortionK2>0.0</distortionK2>
        <distortionK3>0.0</distortionK3>
        <distortionT1>0.0</distortionT1>
        <distortionT2>0.0</distortionT2>
      </plugin>
    </sensor>
    <material value="IPA/LightGrey"/>
    <turnGravityOff>true</turnGravityOff>
  </gazebo>
  <joint name="head_cam3d_joint" type="fixed">
    <origin rpy="1.57079632679 -1.57079632679 0.0" xyz="-0.09 0.095 0.02"/>
    <parent link="head_cam_reference_link"/>
    <child link="head_cam3d_link"/>
  </joint>
  <link name="head_cam3d_link">
    <inertial>
      <mass value="0.01"/>
      <origin rpy="0 0 0" xyz="0 0 0"/>
      <inertia ixx="0.0001" ixy="0" ixz="0" iyy="0.0001" iyz="0" izz="0.0001"/>
    </inertial>
    <visual>
      <origin rpy="0 0 0" xyz="0 0 -0.03"/>
      <geometry>
        <box size="0.06 0.02 0.02"/>
      </geometry>
      <material name="IPA/LightGrey"/>
    </visual>
    <collision>
      <origin rpy="0 0 0" xyz="0 0 -0.03"/>
      <geometry>
        <box size="0.06 0.02 0.02"/>
      </geometry>
    </collision>
  </link>
  <joint name="head_cam3d_frame_joint" type="fixed">
    <origin rpy="1.57079632679 -1.57079632679 0" xyz="0 0 0"/>
    <parent link="head_cam3d_link"/>
    <child link="head_cam3d_frame"/>
  </joint>
  <link name="head_cam3d_frame"/>
  <gazebo reference="head_cam3d_frame">
    <sensor name="head_cam3d_frame_sensor" type="depth">
      <always_on>true</always_on>
      <update_rate>20.0</update_rate>
      <camera>
        <horizontal_fov>1.08210413624</horizontal_fov>
        <image>
          <format>R8G8B8</format>
          <width>640</width>
          <height>480</height>
        </image>
        <clip>
          <near>0.1</near>
          <far>100</far>
        </clip>
      </camera>
      <plugin filename="libgazebo_ros_openni_kinect.so" name="head_cam3d_controller">
        <alwaysOn>true</alwaysOn>
        <updateRate>20.0</updateRate>
        <cameraName>cam3d</cameraName>
        <frameName>head_cam3d_link</frameName>
        <imageTopicName>cam3d/rgb/image_raw</imageTopicName>
        <depthImageTopicName>cam3d/depth/image_raw</depthImageTopicName>
        <pointCloudTopicName>cam3d/depth/points</pointCloudTopicName>
        <cameraInfoTopicName>cam3d/rgb/camera_info</cameraInfoTopicName>
        <depthImageCameraInfoTopicName>cam3d/depth/camera_info</depthImageCameraInfoTopicName>
        <pointCloudCutoff>0.5</pointCloudCutoff>
        <baseline>0.2</baseline>
        <hackBaseline>0.0</hackBaseline>
        <distortionK1>0.0</distortionK1>
        <distortionK2>0.0</distortionK2>
        <distortionK3>0.0</distortionK3>
        <distortionT1>0.0</distortionT1>
        <distortionT2>0.0</distortionT2>
        <CxPrime>0.0</CxPrime>
        <Cx>0.0</Cx>
        <Cy>0.0</Cy>
        <focalLength>0.0</focalLength>
      </plugin>
    </sensor>
    <material>IPA/LightGrey</material>
  </gazebo>
  <gazebo reference="head_axis_link">
    <material>IPA/LightGrey</material>
    <turnGravityOff>false</turnGravityOff>
  </gazebo>
  <transmission name="head_axis_trans">
    <type>transmission_interface/SimpleTransmission</type>
    <joint name="head_axis_joint"/>
    <actuator name="head_axis_motor">
      <hardwareInterface>EffortJointInterface</hardwareInterface>
      <mechanicalReduction>1</mechanicalReduction>
    </actuator>
  </transmission>
  <joint name="lookat_base_joint" type="fixed">
    <origin rpy="3.1415926 3.1415926 3.14159265359" xyz="0.0 -0.154 0.0"/>
    <parent link="torso_upper_neck_tilt_link"/>
    <child link="lookat_base_link"/>
  </joint>
  <link name="lookat_base_link"/>
  <joint name="lookat_lin_joint" type="prismatic">
    <origin rpy="0 0 0" xyz="0 0 0"/>
    <parent link="lookat_base_link"/>
    <child link="lookat_x_link"/>
    <axis xyz="-1 0 0"/>
    <!--axis xyz="-1 0 0" /-->
    <dynamics damping="5.0" friction="0.5"/>
    <limit effort="100" lower="-5.0" upper="5.0" velocity="1"/>
  </joint>
  <link name="lookat_x_link"/>
  <joint name="lookat_x_joint" type="revolute">
    <origin rpy="0 0 0" xyz="0 0 0"/>
    <parent link="lookat_x_link"/>
    <child link="lookat_y_link"/>
    <axis xyz="1 0 0"/>
    <dynamics damping="5.0" friction="0.5"/>
    <limit effort="100" lower="-3.14159265359" upper="3.14159265359" velocity="1"/>
  </joint>
  <link name="lookat_y_link"/>
  <joint name="lookat_y_joint" type="revolute">
    <origin rpy="0 0 0" xyz="0 0 0"/>
    <parent link="lookat_y_link"/>
    <child link="lookat_z_link"/>
    <axis xyz="0 1 0"/>
    <dynamics damping="5.0" friction="0.5"/>
    <limit effort="100" lower="-3.14159265359" upper="3.14159265359" velocity="1"/>
  </joint>
  <link name="lookat_z_link"/>
  <joint name="lookat_z_joint" type="revolute">
    <origin rpy="0 0 0" xyz="0 0 0"/>
    <parent link="lookat_z_link"/>
    <child link="lookat_focus_frame"/>
    <axis xyz="0 0 1"/>
    <dynamics damping="5.0" friction="0.5"/>
    <limit effort="100" lower="-3.14159265359" upper="3.14159265359" velocity="1"/>
  </joint>
  <link name="lookat_focus_frame">
    <!--
      <visual>
        <origin xyz="0 0 0" rpy="0 0 0" />
        <geometry>
          <box size="0.05 0.05 0.2"/>
        </geometry>
        <material name="IPA/Black" />
      </visual>
-->
  </link>
  <joint name="sdh_palm_joint" type="fixed">
    <origin rpy="0.0 0.0 1.5708" xyz="0.0 0.0 0.032"/>
    <parent link="arm_7_link"/>
    <child link="sdh_palm_link"/>
  </joint>
  <link name="sdh_palm_link">
    <inertial>
      <origin rpy="0 0 0" xyz="0 0 0"/>
      <mass value="1"/>
      <inertia ixx="0.01" ixy="0" ixz="0" iyy="0.01" iyz="0" izz="0.01"/>
    </inertial>
    <visual>
      <origin rpy="0 0 0" xyz="0 0 0"/>
      <geometry>
        <mesh filename="package://schunk_description/meshes/sdh/palm.stl"/>
      </geometry>
      <material name="Schunk/LightGrey"/>
    </visual>
    <collision>
      <origin rpy="0 0 0" xyz="0 0 0"/>
      <geometry>
        <mesh filename="package://schunk_description/meshes/sdh/palm.stl"/>
      </geometry>
    </collision>
  </link>
  <joint name="sdh_grasp_joint" type="fixed">
    <origin rpy="0 0 0" xyz="0 0 0.15"/>
    <parent link="sdh_palm_link"/>
    <child link="sdh_grasp_link"/>
  </joint>
  <link name="sdh_grasp_link"/>
  <joint name="sdh_tip_joint" type="fixed">
    <origin rpy="0 0 0" xyz="0 0 0.22"/>
    <parent link="sdh_palm_link"/>
    <child link="sdh_tip_link"/>
  </joint>
  <link name="sdh_tip_link"/>
  <joint name="sdh_knuckle_joint" type="revolute">
    <origin rpy="0 0 3.14159265" xyz="0.01905 0.033 0.0745"/>
    <parent link="sdh_palm_link"/>
    <child link="sdh_finger_11_link"/>
    <axis xyz="0 0 1"/>
    <dynamics damping="1"/>
    <limit effort="100" lower="0" upper="1.570796327" velocity="5"/>
  </joint>
  <link name="sdh_finger_11_link">
    <inertial>
      <origin rpy="0 0 0" xyz="0 0 0"/>
      <mass value="0.1"/>
      <inertia ixx="0.01" ixy="0" ixz="0" iyy="0.01" iyz="0" izz="0.01"/>
    </inertial>
    <visual>
      <origin rpy="0 0 0" xyz="0 0 0"/>
      <geometry>
        <mesh filename="package://schunk_description/meshes/sdh/knuckle.stl"/>
      </geometry>
      <material name="Schunk/LightGrey"/>
    </visual>
    <collision>
      <origin rpy="0 0 0" xyz="0 0 0"/>
      <geometry>
        <mesh filename="package://schunk_description/meshes/sdh/knuckle.stl"/>
      </geometry>
    </collision>
  </link>
  <joint name="sdh_finger_12_joint" type="revolute">
    <origin rpy="0 0 0" xyz="0 0 0.0165"/>
    <parent link="sdh_finger_11_link"/>
    <child link="sdh_finger_12_link"/>
    <axis xyz="0 1 0"/>
    <dynamics damping="1"/>
    <limit effort="100" lower="-1.570796327" upper="1.570796327" velocity="5"/>
  </joint>
  <link name="sdh_finger_12_link">
    <inertial>
      <origin rpy="0 0 0" xyz="0 0 0"/>
      <mass value="0.1"/>
      <inertia ixx="0.01" ixy="0" ixz="0" iyy="0.01" iyz="0" izz="0.01"/>
    </inertial>
    <visual>
      <origin rpy="0 0 0" xyz="0 0 0"/>
      <geometry>
        <mesh filename="package://schunk_description/meshes/sdh/finger.stl"/>
      </geometry>
      <material name="Schunk/LightGrey"/>
    </visual>
    <collision>
      <origin rpy="0 0 0" xyz="0 0 0"/>
      <geometry>
        <mesh filename="package://schunk_description/meshes/sdh/finger.stl"/>
      </geometry>
    </collision>
  </link>
  <joint name="sdh_finger_13_joint" type="revolute">
    <origin rpy="0 0 0" xyz="0 0 0.0865"/>
    <parent link="sdh_finger_12_link"/>
    <child link="sdh_finger_13_link"/>
    <axis xyz="0 1 0"/>
    <dynamics damping="1"/>
    <limit effort="100" lower="-1.570796327" upper="1.570796327" velocity="5"/>
  </joint>
  <link name="sdh_finger_13_link">
    <inertial>
      <origin rpy="0 0 0" xyz="0 0 0"/>
      <mass value="0.1"/>
      <inertia ixx="0.01" ixy="0" ixz="0" iyy="0.01" iyz="0" izz="0.01"/>
    </inertial>
    <visual>
      <origin rpy="0 0 0" xyz="0 0 0"/>
      <geometry>
        <mesh filename="package://schunk_description/meshes/sdh/finger_tip.stl"/>
      </geometry>
      <material name="Schunk/LightGrey"/>
    </visual>
    <collision>
      <origin rpy="0 0 0" xyz="0 0 0"/>
      <geometry>
        <mesh filename="package://schunk_description/meshes/sdh/finger_tip.stl"/>
      </geometry>
    </collision>
  </link>
  <joint name="sdh_finger_21_joint" type="revolute">
    <mimic joint="sdh_knuckle_joint" multiplier="1" offset="0"/>
    <origin rpy="0 0 3.14159265" xyz="0.01905 -0.033 0.0745"/>
    <parent link="sdh_palm_link"/>
    <child link="sdh_finger_21_link"/>
    <axis xyz="0 0 -1"/>
    <dynamics damping="1"/>
    <limit effort="100" lower="0" upper="1.570796327" velocity="5"/>
  </joint>
  <link name="sdh_finger_21_link">
    <inertial>
      <origin rpy="0 0 0" xyz="0 0 0"/>
      <mass value="0.1"/>
      <inertia ixx="0.01" ixy="0" ixz="0" iyy="0.01" iyz="0" izz="0.01"/>
    </inertial>
    <visual>
      <origin rpy="0 0 0" xyz="0 0 0"/>
      <geometry>
        <mesh filename="package://schunk_description/meshes/sdh/knuckle.stl"/>
      </geometry>
      <material name="Schunk/LightGrey"/>
    </visual>
    <collision>
      <origin rpy="0 0 0" xyz="0 0 0"/>
      <geometry>
        <mesh filename="package://schunk_description/meshes/sdh/knuckle.stl"/>
      </geometry>
    </collision>
  </link>
  <joint name="sdh_finger_22_joint" type="revolute">
    <origin rpy="0 0 0" xyz="0 0 0.0165"/>
    <parent link="sdh_finger_21_link"/>
    <child link="sdh_finger_22_link"/>
    <axis xyz="0 1 0"/>
    <dynamics damping="1"/>
    <limit effort="100" lower="-1.570796327" upper="1.570796327" velocity="5"/>
  </joint>
  <link name="sdh_finger_22_link">
    <inertial>
      <origin rpy="0 0 0" xyz="0 0 0"/>
      <mass value="0.1"/>
      <inertia ixx="0.01" ixy="0" ixz="0" iyy="0.01" iyz="0" izz="0.01"/>
    </inertial>
    <visual>
      <origin rpy="0 0 0" xyz="0 0 0"/>
      <geometry>
        <mesh filename="package://schunk_description/meshes/sdh/finger.stl"/>
      </geometry>
      <material name="Schunk/LightGrey"/>
    </visual>
    <collision>
      <origin rpy="0 0 0" xyz="0 0 0"/>
      <geometry>
        <mesh filename="package://schunk_description/meshes/sdh/finger.stl"/>
      </geometry>
    </collision>
  </link>
  <joint name="sdh_finger_23_joint" type="revolute">
    <origin rpy="0 0 0" xyz="0 0 0.0865"/>
    <parent link="sdh_finger_22_link"/>
    <child link="sdh_finger_23_link"/>
    <axis xyz="0 1 0"/>
    <dynamics damping="1"/>
    <limit effort="100" lower="-1.570796327" upper="1.570796327" velocity="5"/>
  </joint>
  <link name="sdh_finger_23_link">
    <inertial>
      <origin rpy="0 0 0" xyz="0 0 0"/>
      <mass value="0.1"/>
      <inertia ixx="0.01" ixy="0" ixz="0" iyy="0.01" iyz="0" izz="0.01"/>
    </inertial>
    <visual>
      <origin rpy="0 0 0" xyz="0 0 0"/>
      <geometry>
        <mesh filename="package://schunk_description/meshes/sdh/finger_tip.stl"/>
      </geometry>
      <material name="Schunk/LightGrey"/>
    </visual>
    <collision>
      <origin rpy="0 0 0" xyz="0 0 0"/>
      <geometry>
        <mesh filename="package://schunk_description/meshes/sdh/finger_tip.stl"/>
      </geometry>
    </collision>
  </link>
  <joint name="sdh_thumb_1_joint" type="fixed">
    <origin rpy="0 0 0" xyz="-0.03811 0 0.0745 "/>
    <parent link="sdh_palm_link"/>
    <child link="sdh_thumb_1_link"/>
  </joint>
  <link name="sdh_thumb_1_link">
    <inertial>
      <origin rpy="0 0 0" xyz="0 0 0"/>
      <mass value="0.1"/>
      <inertia ixx="0.01" ixy="0" ixz="0" iyy="0.01" iyz="0" izz="0.01"/>
    </inertial>
    <visual>
      <origin rpy="0 0 0" xyz="0 0 0"/>
      <geometry>
        <mesh filename="package://schunk_description/meshes/sdh/knuckle.stl"/>
      </geometry>
      <material name="Schunk/LightGrey"/>
    </visual>
    <collision>
      <origin rpy="0 0 0" xyz="0 0 0"/>
      <geometry>
        <mesh filename="package://schunk_description/meshes/sdh/knuckle.stl"/>
      </geometry>
    </collision>
  </link>
  <joint name="sdh_thumb_2_joint" type="revolute">
    <origin rpy="0 0 0" xyz="0 0 0.0165"/>
    <parent link="sdh_thumb_1_link"/>
    <child link="sdh_thumb_2_link"/>
    <axis xyz="0 1 0"/>
    <dynamics damping="1"/>
    <limit effort="100" lower="-1.570796327" upper="1.570796327" velocity="5"/>
  </joint>
  <link name="sdh_thumb_2_link">
    <inertial>
      <origin rpy="0 0 0" xyz="0 0 0"/>
      <mass value="0.1"/>
      <inertia ixx="0.01" ixy="0" ixz="0" iyy="0.01" iyz="0" izz="0.01"/>
    </inertial>
    <visual>
      <origin rpy="0 0 0" xyz="0 0 0"/>
      <geometry>
        <mesh filename="package://schunk_description/meshes/sdh/finger.stl"/>
      </geometry>
      <material name="Schunk/LightGrey"/>
    </visual>
    <collision>
      <origin rpy="0 0 0" xyz="0 0 0"/>
      <geometry>
        <mesh filename="package://schunk_description/meshes/sdh/finger.stl"/>
      </geometry>
    </collision>
  </link>
  <joint name="sdh_thumb_3_joint" type="revolute">
    <origin rpy="0 0 0" xyz="0 0 0.0865"/>
    <parent link="sdh_thumb_2_link"/>
    <child link="sdh_thumb_3_link"/>
    <axis xyz="0 1 0"/>
    <dynamics damping="1"/>
    <limit effort="100" lower="-1.570796327" upper="1.570796327" velocity="5"/>
  </joint>
  <link name="sdh_thumb_3_link">
    <inertial>
      <origin rpy="0 0 0" xyz="0 0 0"/>
      <mass value="0.1"/>
      <inertia ixx="0.01" ixy="0" ixz="0" iyy="0.01" iyz="0" izz="0.01"/>
    </inertial>
    <visual>
      <origin rpy="0 0 0" xyz="0 0 0"/>
      <geometry>
        <mesh filename="package://schunk_description/meshes/sdh/finger_tip.stl"/>
      </geometry>
      <material name="Schunk/LightGrey"/>
    </visual>
    <collision>
      <origin rpy="0 0 0" xyz="0 0 0"/>
      <geometry>
        <mesh filename="package://schunk_description/meshes/sdh/finger_tip.stl"/>
      </geometry>
    </collision>
  </link>
  <gazebo reference="sdh_palm_link">
    <material>Schunk/LightGrey</material>
    <turnGravityOff>false</turnGravityOff>
  </gazebo>
  <gazebo reference="sdh_finger_11_link">
    <material>Schunk/LightGrey</material>
    <turnGravityOff>false</turnGravityOff>
  </gazebo>
  <gazebo reference="sdh_finger_12_link">
    <selfCollide>true</selfCollide>
    <sensor name="sdh_finger_12_contact_sensor" type="contact">
      <always_on>true</always_on>
      <update_rate>100</update_rate>
      <contact>
        <collision>sdh_finger_12_link_geom</collision>
      </contact>
      <plugin filename="libgazebo_ros_bumper.so" name="sdh_finger_12_gazebo_ros_bumper_controller">
        <alwaysOn>true</alwaysOn>
        <updateRate>100.0</updateRate>
        <frameName>sdh_finger_12_link</frameName>
        <bumperTopicName>sdh_finger_12_bumper</bumperTopicName>
      </plugin>
    </sensor>
    <material>Schunk/LightGrey</material>
    <turnGravityOff>false</turnGravityOff>
  </gazebo>
  <gazebo reference="sdh_finger_13_link">
    <selfCollide>true</selfCollide>
    <sensor name="sdh_finger_13_contact_sensor" type="contact">
      <always_on>true</always_on>
      <update_rate>100</update_rate>
      <contact>
        <collision>sdh_finger_13_link_geom</collision>
      </contact>
      <plugin filename="libgazebo_ros_bumper.so" name="sdh_finger_13_gazebo_ros_bumper_controller">
        <alwaysOn>true</alwaysOn>
        <updateRate>100.0</updateRate>
        <frameName>sdh_finger_13_link</frameName>
        <bumperTopicName>sdh_finger_13_bumper</bumperTopicName>
      </plugin>
    </sensor>
    <material>Schunk/LightGrey</material>
  </gazebo>
  <gazebo reference="sdh_finger_21_link">
    <material>Schunk/LightGrey</material>
    <turnGravityOff>true</turnGravityOff>
    <mu1 value="500"/>
    <mu2 value="500"/>
    <kp value="1000000.0"/>
    <kd value="1.0"/>
  </gazebo>
  <gazebo reference="sdh_finger_22_link">
    <selfCollide>true</selfCollide>
    <sensor name="sdh_finger_22_contact_sensor" type="contact">
      <always_on>true</always_on>
      <update_rate>100</update_rate>
      <contact>
        <collision>sdh_finger_22_link_geom</collision>
      </contact>
      <plugin filename="libgazebo_ros_bumper.so" name="sdh_finger_22_gazebo_ros_bumper_controller">
        <alwaysOn>true</alwaysOn>
        <updateRate>100.0</updateRate>
        <frameName>sdh_finger_22_link</frameName>
        <bumperTopicName>sdh_finger_22_bumper</bumperTopicName>
      </plugin>
    </sensor>
    <material>Schunk/LightGrey</material>
    <turnGravityOff>false</turnGravityOff>
  </gazebo>
  <gazebo reference="sdh_finger_23_link">
    <selfCollide>true</selfCollide>
    <sensor name="sdh_finger_23_contact_sensor" type="contact">
      <always_on>true</always_on>
      <update_rate>100</update_rate>
      <contact>
        <collision>sdh_finger_23_link_geom</collision>
      </contact>
      <plugin filename="libgazebo_ros_bumper.so" name="sdh_finger_23_gazebo_ros_bumper_controller">
        <alwaysOn>true</alwaysOn>
        <updateRate>100.0</updateRate>
        <frameName>sdh_finger_23_link</frameName>
        <bumperTopicName>sdh_finger_23_bumper</bumperTopicName>
      </plugin>
    </sensor>
    <material>Schunk/LightGrey</material>
  </gazebo>
  <gazebo reference="sdh_thumb_1_link">
    <material>Schunk/LightGrey</material>
    <turnGravityOff>false</turnGravityOff>
  </gazebo>
  <gazebo reference="sdh_thumb_2_link">
    <selfCollide>true</selfCollide>
    <sensor name="sdh_thumb_2_contact_sensor" type="contact">
      <always_on>true</always_on>
      <update_rate>100</update_rate>
      <contact>
        <collision>sdh_thumb_2_link_geom</collision>
      </contact>
      <plugin filename="libgazebo_ros_bumper.so" name="sdh_thumb_2_gazebo_ros_bumper_controller">
        <alwaysOn>true</alwaysOn>
        <updateRate>100.0</updateRate>
        <frameName>sdh_thumb_2_link</frameName>
        <bumperTopicName>sdh_thumb_2_bumper</bumperTopicName>
      </plugin>
    </sensor>
    <material>Schunk/LightGrey</material>
    <turnGravityOff>false</turnGravityOff>
  </gazebo>
  <gazebo reference="sdh_thumb_3_link">
    <selfCollide>true</selfCollide>
    <sensor name="sdh_thumb_3_contact_sensor" type="contact">
      <always_on>true</always_on>
      <update_rate>100</update_rate>
      <contact>
        <collision>sdh_thumb_3_link_geom</collision>
      </contact>
      <plugin filename="libgazebo_ros_bumper.so" name="sdh_thumb_3_gazebo_ros_bumper_controller">
        <alwaysOn>true</alwaysOn>
        <updateRate>100.0</updateRate>
        <frameName>sdh_thumb_3_link</frameName>
        <bumperTopicName>sdh_thumb_3_bumper</bumperTopicName>
      </plugin>
    </sensor>
    <material>Schunk/LightGrey</material>
  </gazebo>
  <gazebo reference="sdh_finger_21_joint">
    <stopKd value="1.0"/>
    <stopKp value="10000000"/>
    <fudgeFactor value="1.0"/>
    <provideFeedback value="true"/>
  </gazebo>
  <transmission name="sdh_knuckle_trans">
    <type>transmission_interface/SimpleTransmission</type>
    <joint name="sdh_finger_21_joint"/>
    <actuator name="sdh_knuckle_motor">
      <hardwareInterface>EffortJointInterface</hardwareInterface>
      <mechanicalReduction>1</mechanicalReduction>
    </actuator>
  </transmission>
  <transmission name="sdh_knuckle_trans">
    <type>transmission_interface/SimpleTransmission</type>
    <joint name="sdh_knuckle_joint"/>
    <actuator name="sdh_knuckle_motor">
      <hardwareInterface>EffortJointInterface</hardwareInterface>
      <mechanicalReduction>1</mechanicalReduction>
    </actuator>
  </transmission>
  <transmission name="sdh_finger_12_trans">
    <type>transmission_interface/SimpleTransmission</type>
    <joint name="sdh_finger_12_joint"/>
    <actuator name="sdh_finger_12_motor">
      <hardwareInterface>EffortJointInterface</hardwareInterface>
      <mechanicalReduction>1</mechanicalReduction>
    </actuator>
  </transmission>
  <transmission name="sdh_finger_13_trans">
    <type>transmission_interface/SimpleTransmission</type>
    <joint name="sdh_finger_13_joint"/>
    <actuator name="sdh_finger_13_motor">
      <hardwareInterface>EffortJointInterface</hardwareInterface>
      <mechanicalReduction>1</mechanicalReduction>
    </actuator>
  </transmission>
  <transmission name="sdh_finger_22_trans">
    <type>transmission_interface/SimpleTransmission</type>
    <joint name="sdh_finger_22_joint"/>
    <actuator name="sdh_finger_22_motor">
      <hardwareInterface>EffortJointInterface</hardwareInterface>
      <mechanicalReduction>1</mechanicalReduction>
    </actuator>
  </transmission>
  <transmission name="sdh_finger_23_trans">
    <type>transmission_interface/SimpleTransmission</type>
    <joint name="sdh_finger_23_joint"/>
    <actuator name="sdh_finger_23_motor">
      <hardwareInterface>EffortJointInterface</hardwareInterface>
      <mechanicalReduction>1</mechanicalReduction>
    </actuator>
  </transmission>
  <transmission name="sdh_thumb_2_trans">
    <type>transmission_interface/SimpleTransmission</type>
    <joint name="sdh_thumb_2_joint"/>
    <actuator name="sdh_thumb_2_motor">
      <hardwareInterface>EffortJointInterface</hardwareInterface>
      <mechanicalReduction>1</mechanicalReduction>
    </actuator>
  </transmission>
  <transmission name="sdh_thumb_3_trans">
    <type>transmission_interface/SimpleTransmission</type>
    <joint name="sdh_thumb_3_joint"/>
    <actuator name="sdh_thumb_3_motor">
      <hardwareInterface>EffortJointInterface</hardwareInterface>
      <mechanicalReduction>1</mechanicalReduction>
    </actuator>
  </transmission>
</robot>
